<?xml version="1.0" encoding="utf-8"?>
<!-- This URDF was automatically created by SolidWorks to URDF Exporter! Originally created by Stephen Brawner (brawner@gmail.com) 
     Commit Version: 1.6.0-1-g15f4949  Build Version: 1.6.7594.29634
     For more information, please see http://wiki.ros.org/sw_urdf_exporter -->
<robot
  name="agv5_varo">
  <link
    name="base_link">
    <inertial>
      <origin
        xyz="0.115655071541137 3.66284780284332E-12 -0.152485599770737"
        rpy="0 0 0" />
      <mass
        value="15.0721208608483" />
      <inertia
        ixx="0.600714319391966"
        ixy="-1.06755631071889E-08"
        ixz="0.0704617108133668"
        iyy="1.47840362132378"
        iyz="1.10313437830623E-09"
        izz="1.81163408476871" />
    </inertial>
    <visual>
      <origin
        xyz="0 0 0"
        rpy="0 0 0" />
      <geometry>
        <mesh
          filename="package://agv5_varo/meshes/base_link.STL" />
      </geometry>
      <material
        name="">
        <color
          rgba="0.792156862745098 0.819607843137255 0.933333333333333 1" />
      </material>
    </visual>
    <collision>
      <origin
        xyz="0 0 0"
        rpy="0 0 0" />
      <geometry>
        <mesh
          filename="package://agv5_varo/meshes/base_link.STL" />
      </geometry>
    </collision>
  </link>
  <link
    name="Left_Link">
    <inertial>
      <origin
        xyz="6.89226453687297E-13 -0.0166023388404412 3.94517751800549E-13"
        rpy="0 0 0" />
      <mass
        value="0.52936994072617" />
      <inertia
        ixx="0.000772904303756457"
        ixy="-8.70667323830793E-20"
        ixz="-3.67109231972611E-34"
        iyy="0.0013878620871552"
        iyz="6.44417065836E-18"
        izz="0.000772904303756456" />
    </inertial>
    <visual>
      <origin
        xyz="0 0 0"
        rpy="0 0 0" />
      <geometry>
        <mesh
          filename="package://agv5_varo/meshes/Left_Link.STL" />
      </geometry>
      <material
        name="">
        <color
          rgba="0.792156862745098 0.819607843137255 0.933333333333333 1" />
      </material>
    </visual>
    <collision>
      <origin
        xyz="0 0 0"
        rpy="0 0 0" />
      <geometry>
        <mesh
          filename="package://agv5_varo/meshes/Left_Link.STL" />
      </geometry>
    </collision>
  </link>
  <joint
    name="Left_Joint"
    type="continuous">
    <origin
      xyz="0.110000000000006 0.229999999999991 -0.239999999999994"
      rpy="0 0 0" />
    <parent
      link="base_link" />
    <child
      link="Left_Link" />
    <axis
      xyz="0 1 0" />
  </joint>
  <link
    name="Right_Link">
    <inertial>
      <origin
        xyz="3.79141162909491E-13 0.0166023388387576 3.54161144855425E-14"
        rpy="0 0 0" />
      <mass
        value="0.529369940726169" />
      <inertia
        ixx="0.000772904303756456"
        ixy="8.70716048896513E-20"
        ixz="1.91778702835882E-34"
        iyy="0.0013878620871552"
        iyz="2.16984719145409E-18"
        izz="0.000772904303756456" />
    </inertial>
    <visual>
      <origin
        xyz="0 0 0"
        rpy="0 0 0" />
      <geometry>
        <mesh
          filename="package://agv5_varo/meshes/Right_Link.STL" />
      </geometry>
      <material
        name="">
        <color
          rgba="0.792156862745098 0.819607843137255 0.933333333333333 1" />
      </material>
    </visual>
    <collision>
      <origin
        xyz="0 0 0"
        rpy="0 0 0" />
      <geometry>
        <mesh
          filename="package://agv5_varo/meshes/Right_Link.STL" />
      </geometry>
    </collision>
  </link>
  <joint
    name="Right_Joint"
    type="continuous">
    <origin
      xyz="0.110000000000006 -0.230000000000006 -0.239999999999996"
      rpy="0 0 0" />
    <parent
      link="base_link" />
    <child
      link="Right_Link" />
    <axis
      xyz="0 1 0" />
  </joint>
  <link
    name="LFcon_Link">
    <inertial>
      <origin
        xyz="-0.00121269193413109 7.66053886991358E-15 -0.000415480513229205"
        rpy="0 0 0" />
      <mass
        value="0.0257521038737953" />
      <inertia
        ixx="8.61473826778215E-06"
        ixy="5.73714247890305E-21"
        ixz="-5.64302073523239E-07"
        iyy="8.11210346787567E-06"
        iyz="-2.30301065110909E-21"
        izz="4.80769500241318E-06" />
    </inertial>
    <visual>
      <origin
        xyz="0 0 0"
        rpy="0 0 0" />
      <geometry>
        <mesh
          filename="package://agv5_varo/meshes/LFcon_Link.STL" />
      </geometry>
      <material
        name="">
        <color
          rgba="0.792156862745098 0.819607843137255 0.933333333333333 1" />
      </material>
    </visual>
    <collision>
      <origin
        xyz="0 0 0"
        rpy="0 0 0" />
      <geometry>
        <mesh
          filename="package://agv5_varo/meshes/LFcon_Link.STL" />
      </geometry>
    </collision>
  </link>
  <joint
    name="LFcon_Joint"
    type="continuous">
    <origin
      xyz="0.560363870782178 0.190000000000007 -0.244999999999998"
      rpy="0 0 0" />
    <parent
      link="base_link" />
    <child
      link="LFcon_Link" />
    <axis
      xyz="0 0 1" />
  </joint>
  <link
    name="LF_Link">
    <inertial>
      <origin
        xyz="7.59392548843607E-13 -0.00650000000122719 6.66688926287407E-14"
        rpy="0 0 0" />
      <mass
        value="0.0364111988779923" />
      <inertia
        ixx="8.56927811367131E-06"
        ixy="-3.41691763893474E-25"
        ixz="2.71591299799106E-37"
        iyy="1.61103246905048E-05"
        iyz="2.54747297031203E-20"
        izz="8.56927811367131E-06" />
    </inertial>
    <visual>
      <origin
        xyz="0 0 0"
        rpy="0 0 0" />
      <geometry>
        <mesh
          filename="package://agv5_varo/meshes/LF_Link.STL" />
      </geometry>
      <material
        name="">
        <color
          rgba="0.792156862745098 0.819607843137255 0.933333333333333 1" />
      </material>
    </visual>
    <collision>
      <origin
        xyz="0 0 0"
        rpy="0 0 0" />
      <geometry>
        <mesh
          filename="package://agv5_varo/meshes/LF_Link.STL" />
      </geometry>
    </collision>
  </link>
  <joint
    name="LF_Joint"
    type="continuous">
    <origin
      xyz="-0.00786387078217188 0.00649999999998607 -0.0400000000000009"
      rpy="0 0 0" />
    <parent
      link="LFcon_Link" />
    <child
      link="LF_Link" />
    <axis
      xyz="0 1 0" />
  </joint>
  <link
    name="RFcon_Link">
    <inertial>
      <origin
        xyz="-0.00121269193417084 6.7168492989822E-15 -0.000415480513104305"
        rpy="0 0 0" />
      <mass
        value="0.0257521038737953" />
      <inertia
        ixx="8.61473826778217E-06"
        ixy="5.33362144638911E-21"
        ixz="-5.6430207352324E-07"
        iyy="8.11210346787569E-06"
        iyz="-1.85788997095708E-21"
        izz="4.80769500241318E-06" />
    </inertial>
    <visual>
      <origin
        xyz="0 0 0"
        rpy="0 0 0" />
      <geometry>
        <mesh
          filename="package://agv5_varo/meshes/RFcon_Link.STL" />
      </geometry>
      <material
        name="">
        <color
          rgba="0.792156862745098 0.819607843137255 0.933333333333333 1" />
      </material>
    </visual>
    <collision>
      <origin
        xyz="0 0 0"
        rpy="0 0 0" />
      <geometry>
        <mesh
          filename="package://agv5_varo/meshes/RFcon_Link.STL" />
      </geometry>
    </collision>
  </link>
  <joint
    name="RFcon_Joint"
    type="continuous">
    <origin
      xyz="0.560363870782182 -0.189999999999993 -0.244999999999998"
      rpy="0 0 0" />
    <parent
      link="base_link" />
    <child
      link="RFcon_Link" />
    <axis
      xyz="0 0 1" />
  </joint>
  <link
    name="RF_Link">
    <inertial>
      <origin
        xyz="3.59712259978551E-13 0.00649999999876644 7.55506768257419E-14"
        rpy="0 0 0" />
      <mass
        value="0.0364111988779923" />
      <inertia
        ixx="8.56927811367131E-06"
        ixy="1.67531682123137E-26"
        ixz="1.40097792434919E-38"
        iyy="1.61103246905048E-05"
        iyz="2.54747297031203E-20"
        izz="8.56927811367131E-06" />
    </inertial>
    <visual>
      <origin
        xyz="0 0 0"
        rpy="0 0 0" />
      <geometry>
        <mesh
          filename="package://agv5_varo/meshes/RF_Link.STL" />
      </geometry>
      <material
        name="">
        <color
          rgba="0.792156862745098 0.819607843137255 0.933333333333333 1" />
      </material>
    </visual>
    <collision>
      <origin
        xyz="0 0 0"
        rpy="0 0 0" />
      <geometry>
        <mesh
          filename="package://agv5_varo/meshes/RF_Link.STL" />
      </geometry>
    </collision>
  </link>
  <joint
    name="RF_Joint"
    type="continuous">
    <origin
      xyz="-0.00786387078217587 -0.00650000000001394 -0.0400000000000023"
      rpy="0 0 0" />
    <parent
      link="RFcon_Link" />
    <child
      link="RF_Link" />
    <axis
      xyz="0 1 0" />
  </joint>
  <link
    name="LBcon_Link">
    <inertial>
      <origin
        xyz="-0.00121269193412316 9.76996261670138E-14 -0.000415480513484057"
        rpy="0 0 0" />
      <mass
        value="0.0257521038737953" />
      <inertia
        ixx="8.61473826778219E-06"
        ixy="4.64793643123521E-21"
        ixz="-5.64302073523248E-07"
        iyy="8.11210346787571E-06"
        iyz="-9.37517966136664E-21"
        izz="4.80769500241318E-06" />
    </inertial>
    <visual>
      <origin
        xyz="0 0 0"
        rpy="0 0 0" />
      <geometry>
        <mesh
          filename="package://agv5_varo/meshes/LBcon_Link.STL" />
      </geometry>
      <material
        name="">
        <color
          rgba="0.792156862745098 0.819607843137255 0.933333333333333 1" />
      </material>
    </visual>
    <collision>
      <origin
        xyz="0 0 0"
        rpy="0 0 0" />
      <geometry>
        <mesh
          filename="package://agv5_varo/meshes/LBcon_Link.STL" />
      </geometry>
    </collision>
  </link>
  <joint
    name="LBcon_Joint"
    type="continuous">
    <origin
      xyz="-0.239636129217822 0.189999999999999 -0.245000000000001"
      rpy="0 0 0" />
    <parent
      link="base_link" />
    <child
      link="LBcon_Link" />
    <axis
      xyz="0 0 1" />
  </joint>
  <link
    name="LB_Link">
    <inertial>
      <origin
        xyz="7.68218821889377E-13 -0.00650000000038042 1.70974345792274E-14"
        rpy="0 0 0" />
      <mass
        value="0.0364111988779923" />
      <inertia
        ixx="8.56927811367131E-06"
        ixy="3.75198100318771E-25"
        ixz="2.71591299799106E-37"
        iyy="1.61103246905048E-05"
        iyz="2.54747297031203E-20"
        izz="8.56927811367131E-06" />
    </inertial>
    <visual>
      <origin
        xyz="0 0 0"
        rpy="0 0 0" />
      <geometry>
        <mesh
          filename="package://agv5_varo/meshes/LB_Link.STL" />
      </geometry>
      <material
        name="">
        <color
          rgba="0.792156862745098 0.819607843137255 0.933333333333333 1" />
      </material>
    </visual>
    <collision>
      <origin
        xyz="0 0 0"
        rpy="0 0 0" />
      <geometry>
        <mesh
          filename="package://agv5_varo/meshes/LB_Link.STL" />
      </geometry>
    </collision>
  </link>
  <joint
    name="LB_Joint"
    type="continuous">
    <origin
      xyz="-0.00786387078217188 0.00649999999999451 -0.0399999999999985"
      rpy="0 0 0" />
    <parent
      link="LBcon_Link" />
    <child
      link="LB_Link" />
    <axis
      xyz="0 -1 0" />
  </joint>
  <link
    name="RBcon_Link">
    <inertial>
      <origin
        xyz="-0.00121269193416546 9.51461132103759E-14 -0.000415480513359157"
        rpy="0 0 0" />
      <mass
        value="0.0257521038737953" />
      <inertia
        ixx="8.61473826778216E-06"
        ixy="3.6436381704902E-21"
        ixz="-5.64302073523249E-07"
        iyy="8.11210346787568E-06"
        iyz="-1.09936104063131E-20"
        izz="4.80769500241318E-06" />
    </inertial>
    <visual>
      <origin
        xyz="0 0 0"
        rpy="0 0 0" />
      <geometry>
        <mesh
          filename="package://agv5_varo/meshes/RBcon_Link.STL" />
      </geometry>
      <material
        name="">
        <color
          rgba="0.792156862745098 0.819607843137255 0.933333333333333 1" />
      </material>
    </visual>
    <collision>
      <origin
        xyz="0 0 0"
        rpy="0 0 0" />
      <geometry>
        <mesh
          filename="package://agv5_varo/meshes/RBcon_Link.STL" />
      </geometry>
    </collision>
  </link>
  <joint
    name="RBcon_Joint"
    type="continuous">
    <origin
      xyz="-0.239636129217818 -0.190000000000001 -0.245000000000001"
      rpy="0 0 0" />
    <parent
      link="base_link" />
    <child
      link="RBcon_Link" />
    <axis
      xyz="0 0 1" />
  </joint>
  <link
    name="RB_Link">
    <inertial>
      <origin
        xyz="3.65096841647983E-13 0.00649999999961287 2.55351295663786E-14"
        rpy="0 0 0" />
      <mass
        value="0.0364111988779923" />
      <inertia
        ixx="8.56927811367131E-06"
        ixy="1.67531682123137E-26"
        ixz="2.71591299799105E-37"
        iyy="1.61103246905048E-05"
        iyz="2.54747297031203E-20"
        izz="8.56927811367131E-06" />
    </inertial>
    <visual>
      <origin
        xyz="0 0 0"
        rpy="0 0 0" />
      <geometry>
        <mesh
          filename="package://agv5_varo/meshes/RB_Link.STL" />
      </geometry>
      <material
        name="">
        <color
          rgba="0.792156862745098 0.819607843137255 0.933333333333333 1" />
      </material>
    </visual>
    <collision>
      <origin
        xyz="0 0 0"
        rpy="0 0 0" />
      <geometry>
        <mesh
          filename="package://agv5_varo/meshes/RB_Link.STL" />
      </geometry>
    </collision>
  </link>
  <joint
    name="RB_Joint"
    type="continuous">
    <origin
      xyz="-0.00786387078217587 -0.00650000000000545 -0.0399999999999999"
      rpy="0 0 0" />
    <parent
      link="RBcon_Link" />
    <child
      link="RB_Link" />
    <axis
      xyz="0 -1 0" />
  </joint>
  <gazebo>
    <plugin name="controller"   filename="libgazebo_ros_diff_drive.so">
        <leftJoint>Left_Joint</leftJoint>
        <rightJoint>Right_Joint</rightJoint>
        <legacyMode>false</legacyMode>
        <robotBaseFrame>base_link</robotBaseFrame>
        <wheelSeparation>0.4</wheelSeparation>
        <wheelDiameter>0.15</wheelDiameter>
        <publishWheelJointState>true</publishWheelJointState>
    </plugin>
    
</gazebo>
   <gazebo>
    <plugin name="joint_state_publisher"
            filename="libgazebo_ros_joint_state_publisher.so">
        <jointName>LF_Joint, RF_Joint, LB_Joint, RB_Joint, RFcon_Joint, RBcon_Joint, LFcon_Joint, LBcon_Joint</jointName>
    </plugin>
</gazebo>
</robot>